<?xml version="1.0"?>
<robot xmlns:xacro="http://www.ros.org/wiki/xacro"  name="imre_robot">

    <material name="white"><color rgba="1 1 1 1" /></material>
    <material name="orange"><color rgba="1 0.3 0.1 1"/></material>
    <material name="blue"><color rgba="0.2 0.2 1 1"/></material>
    <material name="black"><color rgba="0 0 0 1"/></material>

    <link name="base_link"></link>

    <link name="chassis">
        <visual>
            <origin xyz="0.15 0 0.075"/>
            <geometry><box size="0.3 0.3 0.15"/></geometry>
            <material name="white"/>
        </visual>
        <collision>
            <origin xyz="0.15 0 0.075"/>
            <geometry><box size="0.3 0.3 0.15"/></geometry>
        </collision>
        <inertial>
            <origin xyz="0.15 0 0.075" rpy="0 0 0"/>
            <mass value="2.0" />
            <inertia ixx="0.01" ixy="0.0" ixz="0.0" iyy="0.01" iyz="0.0" izz="0.01" />
        </inertial>
    </link>

    <joint name="chassis_joint" type="fixed">
        <parent link="base_link"/>
        <child link="chassis"/>
        <origin xyz="-0.1 0 0"/>
    </joint>

    <joint name="left_wheel_joint" type="continuous">
        <parent link="base_link"/>
        <child link="left_wheel"/>
        <origin xyz="0 0.175 0" rpy="-1.5708 0 0"/>
        <axis xyz="0 0 1"/>
    </joint>
    <link name="left_wheel">
        <visual><geometry><cylinder radius="0.05" length="0.04"/></geometry><material name="blue"/></visual>
        <collision><geometry><cylinder radius="0.05" length="0.04"/></geometry></collision>
        <inertial><mass value="0.5"/><inertia ixx="0.001" ixy="0" ixz="0" iyy="0.001" iyz="0" izz="0.001"/></inertial>
    </link>

    <joint name="right_wheel_joint" type="continuous">
        <parent link="base_link"/>
        <child link="right_wheel"/>
        <origin xyz="0 -0.175 0" rpy="1.5708 0 0"/>
        <axis xyz="0 0 -1"/>
    </joint>
    <link name="right_wheel">
        <visual><geometry><cylinder radius="0.05" length="0.04"/></geometry><material name="blue"/></visual>
        <collision><geometry><cylinder radius="0.05" length="0.04"/></geometry></collision>
        <inertial><mass value="0.5"/><inertia ixx="0.001" ixy="0" ixz="0" iyy="0.001" iyz="0" izz="0.001"/></inertial>
    </link>

    <joint name="caster_wheel_joint" type="fixed">
        <parent link="chassis"/>
        <child link="caster_wheel"/>
        <origin xyz="0.24 0 0"/>
    </joint>
    <link name="caster_wheel">
        <visual><geometry><sphere radius="0.05"/></geometry><material name="black"/></visual>
        <collision><geometry><sphere radius="0.05"/></geometry></collision>
        <inertial><mass value="0.1"/><inertia ixx="0.0001" ixy="0" ixz="0" iyy="0.0001" iyz="0" izz="0.0001"/></inertial>
    </link>

    <joint name="camera_joint" type="revolute">
        <parent link="chassis"/>
        <child link="camera_link"/>
        <origin xyz="0.3 0 0.15" rpy="0 0 0"/>
        
        <axis xyz="0 1 0"/>
        
        <limit lower="0.0" upper="1.0" effort="20.0" velocity="2.0"/>
        <dynamics damping="0.0" friction="0.0"/>
    </joint>

    <link name="camera_link">
        <visual>
            <geometry><box size="0.05 0.10 0.05"/></geometry>
            <material name="orange"/>
        </visual>
        <collision><geometry><box size="0.05 0.10 0.05"/></geometry></collision>
        <inertial><mass value="0.05"/><inertia ixx="0.0001" ixy="0" ixz="0" iyy="0.0001" iyz="0" izz="0.0001"/></inertial>
    </link>

    <joint name="camera_optical_joint" type="fixed">
        <parent link="camera_link"/>
        <child link="camera_link_optical"/>
        <origin xyz="0 0 0" rpy="-1.5708 0 -1.5708"/>
    </joint>
    <link name="camera_link_optical"></link>


    <gazebo>
        <plugin name="diff_drive" filename="libgazebo_ros_diff_drive.so">
            <left_joint>left_wheel_joint</left_joint>
            <right_joint>right_wheel_joint</right_joint>
            <wheel_separation>0.35</wheel_separation>
            <wheel_diameter>0.1</wheel_diameter>
            <max_wheel_torque>200</max_wheel_torque>
            <max_wheel_acceleration>10.0</max_wheel_acceleration>
            <odometry_frame>odom</odometry_frame>
            <robot_base_frame>base_link</robot_base_frame>
            <publish_odom>true</publish_odom>
            <publish_odom_tf>true</publish_odom_tf>
            <publish_wheel_tf>true</publish_wheel_tf>
        </plugin>
    </gazebo>

    <gazebo reference="camera_link">
        <material>Gazebo/Orange</material>
        <sensor name="camera" type="camera">
            <pose> 0 0 0 0 0 0 </pose>
            <visualize>true</visualize>
            <update_rate>10</update_rate>
            <camera>
                <horizontal_fov>1.089</horizontal_fov>
                <image><format>R8G8B8</format><width>640</width><height>480</height></image>
                <clip><near>0.05</near><far>8.0</far></clip>
            </camera>
            <plugin name="camera_controller" filename="libgazebo_ros_camera.so">
                <frame_name>camera_link_optical</frame_name>
            </plugin>
        </sensor>
    </gazebo>

    <ros2_control name="GazeboSystem" type="system">
        <hardware><plugin>gazebo_ros2_control/GazeboSystem</plugin></hardware>
        <joint name="left_wheel_joint">
            <command_interface name="velocity"><param name="min">-10</param><param name="max">10</param></command_interface>
            <state_interface name="velocity"/><state_interface name="position"/>
        </joint>
        <joint name="right_wheel_joint">
            <command_interface name="velocity"><param name="min">-10</param><param name="max">10</param></command_interface>
            <state_interface name="velocity"/><state_interface name="position"/>
        </joint>
        <joint name="camera_joint">
    <command_interface name="position">
        <param name="min">0.0</param>
        <param name="max">1.0</param>
    </command_interface>
    <state_interface name="velocity"/>
    <state_interface name="position"/>
</joint>
    </ros2_control>

    <gazebo>
        <plugin name="gazebo_ros2_control" filename="libgazebo_ros2_control.so">
            <parameters>$(find imre_description)/config/my_controllers.yaml</parameters>
        </plugin>
    </gazebo>
</robot>
